# 错误处理

在程序运行的过程中，如果发生了错误，可以事先约定返回一个错误代码，这样，就可以知道是否有错，以及出错的原因。

高级语言通常都内置了一套 `try...except...finally...` 的错误处理机制，Python 也不例外。

## `try...except...finally...`

当我们认为某些代码可能会出错时，就可以用 `try` 来运行这段代码。

如果执行出错，则后续代码不会继续执行，而是直接跳转至错误处理代码，即 `except` 语句块。

执行完 `except` 后，如果有 `finally` 语句块，则执行 `finally` 语句块。

```python
try:
    print('try ...')
    r = 10 / 0
    print('result: ', r)
except ZeroDivisionError as e:
    print('except: ', e)
finally:
    print('finally...')
# try ...
# except:  division by zero
# finally...
```

## 多个 `except`

如果发生了不同类型的错误，应该由不同的 `except` 语句块处理：

```python
try:
    print('try...')
    r = 10 / int('a')
    print('result:', r)
except ValueError as e:
    print('ValueError:', e)
except ZeroDivisionError as e:
    print('ZeroDivisionError:', e)
finally:
    print('finally...')
# try...
# ValueError: invalid literal for int() with base 10: 'a'
# finally...
```

## `except ... else ...`

如果没有错误发生，可以在 `except` 语句块后面加一个 `else`，当没有错误发生时，会自动执行 `else` 语句：

```python
try:
    print('try...')
    r = 10 / int('2')
    print('result:', r)
except ValueError as e:
    print('ValueError:', e)
except ZeroDivisionError as e:
    print('ZeroDivisionError:', e)
else:
    print('no error!')
finally:
    print('finally...')
# try...
# result: 5.0
# no error!
# finally...
```

## Python 错误

Python 的错误其实也是 `class`，所有的错误类型都继承自 `BaseException`。

所以在使用 `except` 时需要注意的是，它不但捕获该类型的错误，还把其子类也“一网打尽”。

```python
try:
    foo()
except ValueError as e:
    print('ValueError')
except UnicodeError as e:
    print('UnicodeError')
```

第二个 `except` 永远也捕获不到 `UnicodeError`。

因为 `UnicodeError` 是 `ValueError` 的子类，就算有 `UnicodeError` 错误，也被第一个 `except` 给捕获了。

## 常见的错误类型和继承关系

常见的错误类型和继承关系看[这里](https://docs.python.org/3/library/exceptions.html#exception-hierarchy)。

```bash
BaseException
 ├── BaseExceptionGroup
 ├── GeneratorExit
 ├── KeyboardInterrupt
 ├── SystemExit
 └── Exception
      ├── ArithmeticError
      │    ├── FloatingPointError
      │    ├── OverflowError
      │    └── ZeroDivisionError
      ├── AssertionError
      ├── AttributeError
      ├── BufferError
      ├── EOFError
      ├── ExceptionGroup [BaseExceptionGroup]
      ├── ImportError
      │    └── ModuleNotFoundError
      ├── LookupError
      │    ├── IndexError
      │    └── KeyError
      ├── MemoryError
      ├── NameError
      │    └── UnboundLocalError
      ├── OSError
      │    ├── BlockingIOError
      │    ├── ChildProcessError
      │    ├── ConnectionError
      │    │    ├── BrokenPipeError
      │    │    ├── ConnectionAbortedError
      │    │    ├── ConnectionRefusedError
      │    │    └── ConnectionResetError
      │    ├── FileExistsError
      │    ├── FileNotFoundError
      │    ├── InterruptedError
      │    ├── IsADirectoryError
      │    ├── NotADirectoryError
      │    ├── PermissionError
      │    ├── ProcessLookupError
      │    └── TimeoutError
      ├── ReferenceError
      ├── RuntimeError
      │    ├── NotImplementedError
      │    └── RecursionError
      ├── StopAsyncIteration
      ├── StopIteration
      ├── SyntaxError
      │    └── IndentationError
      │         └── TabError
      ├── SystemError
      ├── TypeError
      ├── ValueError
      │    └── UnicodeError
      │         ├── UnicodeDecodeError
      │         ├── UnicodeEncodeError
      │         └── UnicodeTranslateError
      └── Warning
           ├── BytesWarning
           ├── DeprecationWarning
           ├── EncodingWarning
           ├── FutureWarning
           ├── ImportWarning
           ├── PendingDeprecationWarning
           ├── ResourceWarning
           ├── RuntimeWarning
           ├── SyntaxWarning
           ├── UnicodeWarning
           └── UserWarning
```

## 跨层调用

使用 `try...except` 捕获错误还有一个巨大的好处，就是可以跨越多层调用。

比如函数 `main()` 调用 `bar()`，`bar()` 调用 `foo()`，结果 `foo()` 出错了，这时，只要 `main()` 捕获到了，就可以处理：

```python
def foo(s):
    return 10 / int(s)

def bar(s):
    return foo(s) * 2

def main():
    try:
        bar('0')
    except Exception as e:
        print('Error:', e)
    finally:
        print('finally...')

main()
# Error: division by zero
# finally...
```

不需要在每个可能出错的地方去捕获错误，只要在合适的层次去捕获错误就可以了。

这样一来，就大大减少了写 `try...except...finally` 的麻烦。

## 调用栈

如果错误没有被捕获，它就会一直往上抛，最后被 Python 解释器捕获，打印一个错误信息，然后程序退出。

```python
# err.py:
def foo(s):
    return 10 / int(s)

def bar(s):
    return foo(s) * 2

def main():
    bar('0')

main()
# Traceback (most recent call last):
#   File "<stdin>", line 1, in <module>
#   File "<stdin>", line 2, in main
#   File "<stdin>", line 2, in bar
#   File "<stdin>", line 2, in foo
# ZeroDivisionError: division by zero
print('END')
# END
```

Python 会从外层，不断往里调用，直到找到错误产生的源头，然后打印出错误。

最后一个调用栈即是错误的源头。

所以我们只要看最后一个调用栈就好了，

在这里就是 `File "<stdin>", line 2, in foo`，即 `foo` 函数里面的第二行。

## 记录错误 —— `logging` 模块

如果不捕获错误，自然可以让 Python 解释器来打印出错误堆栈，但程序也被结束了。

既然我们能捕获错误，就可以把错误堆栈打印出来，然后分析错误原因，同时，让程序继续执行下去。

Python 内置的 `logging` 模块可以非常容易地记录错误信息：

```python
# err_logging.py
import logging

def foo(s):
    return 10 / int(s)

def bar(s):
    return foo(s) * 2

def main():
    try:
        bar('0')
    except Exception as e:
        logging.exception(e)

main()
# ERROR:root:division by zero
# Traceback (most recent call last):
#   File "<stdin>", line 3, in main
#   File "<stdin>", line 2, in bar
#   File "<stdin>", line 2, in foo
# ZeroDivisionError: division by zero
print('END')
# END
```

这样即使出错了，程序打印完错误信息后，仍会继续执行，并正常退出。

通过配置，`logging` 还可以把错误记录到日志文件里，方便事后排查。

## 抛出错误

因为错误是 `class`，捕获一个错误就是捕获到该 `class` 的一个实例。

因此，错误并不是凭空产生的，而是有意创建并抛出的。

Python 的内置函数会抛出很多类型的错误，我们自己编写的函数也可以抛出错误。

如果要抛出错误，可以

1. 根据需要定义一个错误的 `class`，选择好继承关系，

2. 用 `raise` 语句抛出一个错误的实例。

比如：

```python
def foo(s):
    n = int(s)
    if n == 0:
        raise ValueError('invalid value: %s' % s)
    return 10 / n

def bar():
    try:
        foo('0')
    except ValueError as e:
        print('ValueError!')
        raise

bar()
# ValueError!
# Traceback (most recent call last):
#   File "<stdin>", line 1, in <module>
#   File "<stdin>", line 3, in bar
#   File "<stdin>", line 4, in foo
# ValueError: invalid value: 0
```

在 `bar` 函数中，我们捕获了错误，打印一个 `ValueError!` 后，又把错误通过 `raise` 语句抛出去了。

这是一种很常见的处理方式。

捕获错误目的只是记录一下，便于后续追踪。

由于当前函数不知道应该怎么处理该错误，所以，最恰当的方式是继续往上抛，让顶层调用者去处理。

`raise` 语句如果不带参数，就会把当前错误原样抛出。

此外，在 `except` 中 `raise` 一个 `Error`，还可以把一种类型的错误转化成另一种类型。

```python
try:
    10 / 0
except ZeroDivisionError:
    raise ValueError('input error!')
# Traceback (most recent call last):
#   File "<stdin>", line 2, in <module>
# ZeroDivisionError: division by zero

# During handling of the above exception, another exception occurred:

# Traceback (most recent call last):
#   File "<stdin>", line 4, in <module>
# ValueError: input error!
```

> 但要注意，逻辑合理的话，可以转换。
>
> 但是，把一个 `IOError` 转换成毫不相干的 `ValueError`，就毫无逻辑，完全不合理了。

> 我们自己写的程序如果要抛出错误，那应该在文档中写清楚可能会抛出哪些错误，以及错误产生的原因。
